2025-09-18 10:41:55,676 DEBUG    root            Loaded Command Group: ['gcloud', 'config']
2025-09-18 10:41:55,680 DEBUG    root            Loaded Command Group: ['gcloud', 'config', 'list']
2025-09-18 10:41:55,680 DEBUG    root            Running [gcloud.config.list] with arguments: []
2025-09-18 10:41:55,682 DEBUG    root            Chosen display Format:config
2025-09-18 10:41:55,682 INFO     root            Display format: "config"
2025-09-18 10:41:55,698 INFO     ___FILE_ONLY___ [core]
disable_usage_reporting = True

2025-09-18 10:41:55,698 INFO     ___FILE_ONLY___ 
Your active configuration is: [default]

2025-09-18 10:41:55,701 DEBUG    root            Checking for updates...
2025-09-18 10:41:55,713 DEBUG    urllib3.connectionpool Starting new HTTPS connection (1): dl.google.com:443
2025-09-18 10:41:55,714 DEBUG    root            Failed to perform update check.
Traceback (most recent call last):
  File "/Users/sn/google-cloud-sdk/lib/third_party/urllib3/connection.py", line 198, in _new_conn
    sock = connection.create_connection(
           ^^^^^^^^^^^^^^^^^^^^^^^^^^^^^
  File "/Users/sn/google-cloud-sdk/lib/third_party/urllib3/util/connection.py", line 62, in create_connection
    for res in socket.getaddrinfo(host, port, family, socket.SOCK_STREAM):
               ^^^^^^^^^^^^^^^^^^^^^^^^^^^^^^^^^^^^^^^^^^^^^^^^^^^^^^^^^^
  File "/Library/Frameworks/Python.framework/Versions/3.12/lib/python3.12/socket.py", line 963, in getaddrinfo
    for res in _socket.getaddrinfo(host, port, family, type, proto, flags):
               ^^^^^^^^^^^^^^^^^^^^^^^^^^^^^^^^^^^^^^^^^^^^^^^^^^^^^^^^^^^
socket.gaierror: [Errno 8] nodename nor servname provided, or not known

The above exception was the direct cause of the following exception:

Traceback (most recent call last):
  File "/Users/sn/google-cloud-sdk/lib/third_party/urllib3/connectionpool.py", line 789, in urlopen
    response = self._make_request(
               ^^^^^^^^^^^^^^^^^^^
  File "/Users/sn/google-cloud-sdk/lib/third_party/urllib3/connectionpool.py", line 490, in _make_request
    raise new_e
  File "/Users/sn/google-cloud-sdk/lib/third_party/urllib3/connectionpool.py", line 466, in _make_request
    self._validate_conn(conn)
  File "/Users/sn/google-cloud-sdk/lib/third_party/urllib3/connectionpool.py", line 1098, in _validate_conn
    conn.connect()
  File "/Users/sn/google-cloud-sdk/lib/third_party/urllib3/connection.py", line 620, in connect
    self.sock = sock = self._new_conn()
                       ^^^^^^^^^^^^^^^^
  File "/Users/sn/google-cloud-sdk/lib/third_party/urllib3/connection.py", line 206, in _new_conn
    raise NameResolutionError(self.host, self, e) from e
urllib3.exceptions.NameResolutionError: <urllib3.connection.HTTPSConnection object at 0x10532e180>: Failed to resolve 'dl.google.com' ([Errno 8] nodename nor servname provided, or not known)

The above exception was the direct cause of the following exception:

Traceback (most recent call last):
  File "/Users/sn/google-cloud-sdk/lib/third_party/requests/adapters.py", line 667, in send
    resp = conn.urlopen(
           ^^^^^^^^^^^^^
  File "/Users/sn/google-cloud-sdk/lib/third_party/urllib3/connectionpool.py", line 843, in urlopen
    retries = retries.increment(
              ^^^^^^^^^^^^^^^^^^
  File "/Users/sn/google-cloud-sdk/lib/third_party/urllib3/util/retry.py", line 520, in increment
    raise MaxRetryError(_pool, url, reason) from reason  # type: ignore[arg-type]
    ^^^^^^^^^^^^^^^^^^^^^^^^^^^^^^^^^^^^^^^^^^^^^^^^^^^
urllib3.exceptions.MaxRetryError: HTTPSConnectionPool(host='dl.google.com', port=443): Max retries exceeded with url: /dl/cloudsdk/channels/rapid/components-2.json (Caused by NameResolutionError("<urllib3.connection.HTTPSConnection object at 0x10532e180>: Failed to resolve 'dl.google.com' ([Errno 8] nodename nor servname provided, or not known)"))

During handling of the above exception, another exception occurred:

Traceback (most recent call last):
  File "/Users/sn/google-cloud-sdk/lib/googlecloudsdk/gcloud_main.py", line 62, in UpdateCheck
    update_manager.UpdateManager.PerformUpdateCheck(command_path=command_path)
  File "/Users/sn/google-cloud-sdk/lib/googlecloudsdk/core/updater/update_manager.py", line 315, in PerformUpdateCheck
    manager._PerformUpdateCheck(command_path, force=force)
  File "/Users/sn/google-cloud-sdk/lib/googlecloudsdk/core/updater/update_manager.py", line 732, in _PerformUpdateCheck
    (_, diff) = self._GetStateAndDiff(
                ^^^^^^^^^^^^^^^^^^^^^^
  File "/Users/sn/google-cloud-sdk/lib/googlecloudsdk/core/updater/update_manager.py", line 686, in _GetStateAndDiff
    latest_snapshot = self._GetLatestSnapshot(version=version,
                      ^^^^^^^^^^^^^^^^^^^^^^^^^^^^^^^^^^^^^^^^
  File "/Users/sn/google-cloud-sdk/lib/googlecloudsdk/core/updater/update_manager.py", line 669, in _GetLatestSnapshot
    return snapshots.ComponentSnapshot.FromURLs(
           ^^^^^^^^^^^^^^^^^^^^^^^^^^^^^^^^^^^^^
  File "/Users/sn/google-cloud-sdk/lib/googlecloudsdk/core/updater/snapshots.py", line 176, in FromURLs
    (ComponentSnapshot._DictFromURL(
     ^^^^^^^^^^^^^^^^^^^^^^^^^^^^^^^
  File "/Users/sn/google-cloud-sdk/lib/googlecloudsdk/core/updater/snapshots.py", line 200, in _DictFromURL
    response = installers.MakeRequest(url, command_path)
               ^^^^^^^^^^^^^^^^^^^^^^^^^^^^^^^^^^^^^^^^^
  File "/Users/sn/google-cloud-sdk/lib/googlecloudsdk/core/updater/installers.py", line 115, in MakeRequest
    return _RawRequest(url, headers=headers, timeout=timeout)
           ^^^^^^^^^^^^^^^^^^^^^^^^^^^^^^^^^^^^^^^^^^^^^^^^^^
  File "/Users/sn/google-cloud-sdk/lib/googlecloudsdk/core/updater/installers.py", line 163, in _RawRequest
    return retryer.RetryOnException(
           ^^^^^^^^^^^^^^^^^^^^^^^^^
  File "/Users/sn/google-cloud-sdk/lib/googlecloudsdk/core/util/retry.py", line 201, in RetryOnException
    exceptions.reraise(exc_info[1], tb=exc_info[2])
  File "/Users/sn/google-cloud-sdk/lib/googlecloudsdk/core/exceptions.py", line 149, in reraise
    six.reraise(type(exc_value), exc_value, tb)
  File "/Users/sn/google-cloud-sdk/lib/third_party/six/__init__.py", line 719, in reraise
    raise value
  File "/Users/sn/google-cloud-sdk/lib/googlecloudsdk/core/util/retry.py", line 182, in TryFunc
    return func(*args, **kwargs), None
           ^^^^^^^^^^^^^^^^^^^^^
  File "/Users/sn/google-cloud-sdk/lib/googlecloudsdk/core/updater/installers.py", line 196, in _ExecuteRequestAndRaiseExceptions
    response = requests_session.get(
               ^^^^^^^^^^^^^^^^^^^^^
  File "/Users/sn/google-cloud-sdk/lib/third_party/requests/sessions.py", line 602, in get
    return self.request("GET", url, **kwargs)
           ^^^^^^^^^^^^^^^^^^^^^^^^^^^^^^^^^^
  File "/Users/sn/google-cloud-sdk/lib/googlecloudsdk/core/transport.py", line 280, in WrappedRequest
    response = orig_request(*modified_args, **modified_kwargs)
               ^^^^^^^^^^^^^^^^^^^^^^^^^^^^^^^^^^^^^^^^^^^^^^^
  File "/Users/sn/google-cloud-sdk/lib/googlecloudsdk/core/requests.py", line 280, in WrappedRequest
    return orig_request_method(*args, **kwargs)
           ^^^^^^^^^^^^^^^^^^^^^^^^^^^^^^^^^^^^
  File "/Users/sn/google-cloud-sdk/lib/third_party/requests/sessions.py", line 589, in request
    resp = self.send(prep, **send_kwargs)
           ^^^^^^^^^^^^^^^^^^^^^^^^^^^^^^
  File "/Users/sn/google-cloud-sdk/lib/third_party/requests/sessions.py", line 703, in send
    r = adapter.send(request, **kwargs)
        ^^^^^^^^^^^^^^^^^^^^^^^^^^^^^^^
  File "/Users/sn/google-cloud-sdk/lib/third_party/requests/adapters.py", line 700, in send
    raise ConnectionError(e, request=request)
requests.exceptions.ConnectionError: HTTPSConnectionPool(host='dl.google.com', port=443): Max retries exceeded with url: /dl/cloudsdk/channels/rapid/components-2.json (Caused by NameResolutionError("<urllib3.connection.HTTPSConnection object at 0x10532e180>: Failed to resolve 'dl.google.com' ([Errno 8] nodename nor servname provided, or not known)"))
